[2023-04-16T21:48:40.938+0530] {taskinstance.py:1090} INFO - Dependencies all met for dep_context=non-requeueable deps ti=<TaskInstance: Lead_scoring_training_pipeline.encoding_categorical_variables manual__2023-04-16T16:18:27.597671+00:00 [queued]>
[2023-04-16T21:48:40.943+0530] {taskinstance.py:1090} INFO - Dependencies all met for dep_context=requeueable deps ti=<TaskInstance: Lead_scoring_training_pipeline.encoding_categorical_variables manual__2023-04-16T16:18:27.597671+00:00 [queued]>
[2023-04-16T21:48:40.944+0530] {taskinstance.py:1288} INFO - 
--------------------------------------------------------------------------------
[2023-04-16T21:48:40.944+0530] {taskinstance.py:1289} INFO - Starting attempt 2 of 2
[2023-04-16T21:48:40.944+0530] {taskinstance.py:1290} INFO - 
--------------------------------------------------------------------------------
[2023-04-16T21:48:40.972+0530] {taskinstance.py:1309} INFO - Executing <Task(PythonOperator): encoding_categorical_variables> on 2023-04-16 16:18:27.597671+00:00
[2023-04-16T21:48:40.976+0530] {standard_task_runner.py:55} INFO - Started process 39872 to run task
[2023-04-16T21:48:40.978+0530] {standard_task_runner.py:82} INFO - Running: ['airflow', 'tasks', 'run', 'Lead_scoring_training_pipeline', 'encoding_categorical_variables', 'manual__2023-04-16T16:18:27.597671+00:00', '--job-id', '21', '--raw', '--subdir', 'DAGS_FOLDER/Lead_scoring_training_pipeline/lead_scoring_training_pipeline.py', '--cfg-path', '/tmp/tmpew3ux6pv']
[2023-04-16T21:48:40.979+0530] {standard_task_runner.py:83} INFO - Job 21: Subtask encoding_categorical_variables
[2023-04-16T21:48:41.021+0530] {task_command.py:389} INFO - Running <TaskInstance: Lead_scoring_training_pipeline.encoding_categorical_variables manual__2023-04-16T16:18:27.597671+00:00 [running]> on host pop-os.localdomain
[2023-04-16T21:48:41.059+0530] {taskinstance.py:1516} INFO - Exporting the following env vars:
AIRFLOW_CTX_DAG_OWNER=airflow
AIRFLOW_CTX_DAG_ID=Lead_scoring_training_pipeline
AIRFLOW_CTX_TASK_ID=encoding_categorical_variables
AIRFLOW_CTX_EXECUTION_DATE=2023-04-16T16:18:27.597671+00:00
AIRFLOW_CTX_TRY_NUMBER=2
AIRFLOW_CTX_DAG_RUN_ID=manual__2023-04-16T16:18:27.597671+00:00
[2023-04-16T21:48:41.061+0530] {logging_mixin.py:137} INFO - Loading model_input table
[2023-04-16T21:48:41.061+0530] {taskinstance.py:1776} ERROR - Task failed with exception
Traceback (most recent call last):
  File "/home/nightfall/anaconda3/envs/ml/lib/python3.9/site-packages/pandas/io/sql.py", line 2018, in execute
    cur.execute(*args, **kwargs)
sqlite3.OperationalError: no such table: model_input

The above exception was the direct cause of the following exception:

Traceback (most recent call last):
  File "/home/nightfall/anaconda3/envs/ml/lib/python3.9/site-packages/airflow/operators/python.py", line 175, in execute
    return_value = self.execute_callable()
  File "/home/nightfall/anaconda3/envs/ml/lib/python3.9/site-packages/airflow/operators/python.py", line 192, in execute_callable
    return self.python_callable(*self.op_args, **self.op_kwargs)
  File "/home/nightfall/airflow/code/dags/Lead_scoring_training_pipeline/utils.py", line 110, in encode_features
    df = pd.read_sql("select * from model_input", cnx)
  File "/home/nightfall/anaconda3/envs/ml/lib/python3.9/site-packages/pandas/io/sql.py", line 564, in read_sql
    return pandas_sql.read_query(
  File "/home/nightfall/anaconda3/envs/ml/lib/python3.9/site-packages/pandas/io/sql.py", line 2078, in read_query
    cursor = self.execute(*args)
  File "/home/nightfall/anaconda3/envs/ml/lib/python3.9/site-packages/pandas/io/sql.py", line 2030, in execute
    raise ex from exc
pandas.errors.DatabaseError: Execution failed on sql 'select * from model_input': no such table: model_input
[2023-04-16T21:48:41.063+0530] {taskinstance.py:1327} INFO - Marking task as FAILED. dag_id=Lead_scoring_training_pipeline, task_id=encoding_categorical_variables, execution_date=20230416T161827, start_date=20230416T161840, end_date=20230416T161841
[2023-04-16T21:48:41.088+0530] {standard_task_runner.py:100} ERROR - Failed to execute job 21 for task encoding_categorical_variables (Execution failed on sql 'select * from model_input': no such table: model_input; 39872)
[2023-04-16T21:48:41.110+0530] {local_task_job.py:212} INFO - Task exited with return code 1
[2023-04-16T21:48:41.120+0530] {taskinstance.py:2596} INFO - 0 downstream tasks scheduled from follow-on schedule check
